[2018-11-14 09:45:58,572][140090868187664][data_read_file_server.py][line: 46][ERROR] ## 加载停用词时发生异常Load_stopword'NoneType' object has no attribute 'download_file_by_id'
[2018-11-14 09:45:58,572][140090868187664][data_read_file_server.py][line: 47][ERROR] ## (<class 'AttributeError'>, AttributeError("'NoneType' object has no attribute 'download_file_by_id'",), <traceback object at 0x7f69726fd1c8>)
Traceback (most recent call last):
  File "/home/nlp/qianyan/Find_new_words_Utry/data_read_file_server.py", line 37, in load_stopword
    text = file.download_file_by_id(stopwordID)
AttributeError: 'NoneType' object has no attribute 'download_file_by_id'
[2018-11-14 09:45:58,573][140090868187664][index.py][line: 73][ERROR] ## 获取新词发生异常find_new_word加载停用词时发生异常Load_stopword'NoneType' object has no attribute 'download_file_by_id'
[2018-11-14 09:45:58,573][140090868187664][index.py][line: 74][ERROR] ## (<class 'TypeError'>, TypeError("加载停用词时发生异常Load_stopword'NoneType' object has no attribute 'download_file_by_id'",), <traceback object at 0x7f69727103c8>)
Traceback (most recent call last):
  File "/home/nlp/qianyan/Find_new_words_Utry/data_read_file_server.py", line 37, in load_stopword
    text = file.download_file_by_id(stopwordID)
AttributeError: 'NoneType' object has no attribute 'download_file_by_id'

During handling of the above exception, another exception occurred:

Traceback (most recent call last):
  File "/home/nlp/qianyan/Find_new_words_Utry/index.py", line 54, in find_new_word
    r, PMI_min, PMI_max = dfs.get_new_word_string(file, stopwordID, dicwordID, dataID, text, N, PMI)
  File "/home/nlp/qianyan/Find_new_words_Utry/demo_file_server.py", line 27, in get_new_word_string
    data_read.load_stopword(file, stopwordID)
  File "/home/nlp/qianyan/Find_new_words_Utry/data_read_file_server.py", line 48, in load_stopword
    raise TypeError(s)
TypeError: 加载停用词时发生异常Load_stopword'NoneType' object has no attribute 'download_file_by_id'
